Workbook

Sheet Finance
A1: ROUND | B1: -2 | C1: -1 | D1: 0 | E1: 1 | F1: 2 | G1: 3 | H1: 4 | I1: 5 | J1: 6
A2: ROI | B2: =B37/B85 -> -0.044706112 | C2: =C37/C85 -> -0.037977412 | D2: =D37/D85 -> -0.037977412 | E2: =E37/E85 -> -0.037977412 | F2: =F37/F85 -> -0.069681176 | G2: =G37/G85 -> 0.026164127 | H2: =H37/H85 -> -0.2135201 | I2: =I37/I85 -> #DIV/0!
A5: Realized revenue | B5: =sum(B10,B6) -> 2491636.8 | C5: =sum(C10,C6) -> 2526063 | D5: =sum(D10,D6) -> 2526063 | E5: =sum(E10,E6) -> 2526063 | F5: =sum(F10,F6) -> 2443304.6 | G5: =sum(G10,G6) -> 2838118.1 | H5: =sum(H10,H6) -> 2157046.5 | I5: =sum(I10,I6) -> 0
A6: Contracted sales revenue | B6: =sum(B7:B9) -> 3193657.5 | C6: =sum(C7:C9) -> 3193657.5 | D6: =sum(D7:D9) -> 3193657.5 | E6: =sum(E7:E9) -> 3193657.5 | F6: =sum(F7:F9) -> 3340943.3 | G6: =sum(G7:G9) -> 2518823 | H6: =sum(H7:H9) -> 2983349.1 | I6: =sum(I7:I9) -> 0
A7: All-Round | B7: 1578332.8 | C7: 1578332.8 | D7: 1578332.8 | E7: 1578332.8 | F7: 1694262.6 | G7: 1219869.1 | H7: 1490951.1
A8: Domus | B8: 805569.69 | C8: 805569.69 | D8: 805569.69 | E8: 805569.69 | F8: 817230.98 | G8: 558130.29 | H8: 694384.03
A9: Tecco | B9: 809755.01 | C9: 809755.01 | D9: 809755.01 | E9: 809755.01 | F9: 829449.71 | G9: 740823.58 | H9: 798013.94
A10: Bonus or penalties | B10: =sum(B11:B13) -> -702020.71 | C10: =sum(C11:C13) -> -667594.43 | D10: =sum(D11:D13) -> -667594.43 | E10: =sum(E11:E13) -> -667594.43 | F10: =sum(F11:F13) -> -897638.75 | G10: =sum(G11:G13) -> 319295.16 | H10: =sum(H11:H13) -> -826302.59 | I10: =sum(I11:I13) -> 0
A11: All-Round | B11: -451812.82 | C11: -451812.82 | D11: -451812.82 | E11: -451812.82 | F11: -451803.36 | G11: 180429.47 | H11: -451803.36
A12: Domus | B12: -218588.01 | C12: -196377.35 | D12: -196377.35 | E12: -196377.35 | F12: -218588.89 | G12: 96120.074 | H12: -218588.89
A13: Tecco | B13: -31619.883 | C13: -19404.26 | D13: -19404.26 | E13: -19404.26 | F13: -227246.5 | G13: 42745.615 | H13: -155910.33
A18: Gross Margin | B18: =B5-B19 -> 925196.47 | C18: =C5-C19 -> 956272.63 | D18: =D5-D19 -> 956272.63 | E18: =E5-E19 -> 956272.63 | F18: =F5-F19 -> 832161.43 | G18: =G5-G19 -> 1218092.4 | H18: =H5-H19 -> 138234.75 | I18: =I5-I19 -> 0
A19: COGS | B19: =sum(B26,B20) -> 1566440.3 | C19: =sum(C26,C20) -> 1569790.4 | D19: =sum(D26,D20) -> 1569790.4 | E19: =sum(E26,E20) -> 1569790.4 | F19: =sum(F26,F20) -> 1611143.1 | G19: =sum(G26,G20) -> 1620025.7 | H19: =sum(H26,H20) -> 2018811.7 | I19: =sum(I26,I20) -> 0
A20: Purchase Value | B20: =SUM(B21:B25 ) -> 1037577.5 | C20: =SUM(C21:C25 ) -> 1040176.1 | D20: =SUM(D21:D25 ) -> 1040176.1 | E20: =SUM(E21:E25 ) -> 1040176.1 | F20: =SUM(F21:F25 ) -> 1058500.4 | G20: =SUM(G21:G25 ) -> 1067862.4 | H20: =SUM(H21:H25 ) -> 1012953.2 | I20: =SUM(I21:I25 ) -> 0
A21: Vredenburgh | B21: 95590.508 | C21: 96052.369 | D21: 96052.369 | E21: 96052.369 | F21: 100523.11 | G21: 101201.78 | H21: 95627.199
A22: J. d'Arc PET | B22: 300592.51 | C22: 301551.88 | D22: 301551.88 | E22: 301551.88 | F22: 311341.68 | G22: 307466.16 | H22: 291334.18
A23: Corcovado Oranges | B23: 465443.53 | C23: 466715.05 | D23: 466715.05 | E23: 466715.05 | F23: 468400.54 | G23: 477474.23 | H23: 453618.22
A24: Ouagadougou Fruits | B24: 110431.03 | C24: 110431.03 | D24: 110431.03 | E24: 110431.03 | F24: 112341.54 | G24: 115191.27 | H24: 108526.94
A25: Kão Yã Vitamins | B25: 65519.94 | C25: 65425.776 | D25: 65425.776 | E25: 65425.776 | F25: 65893.576 | G25: 66528.923 | H25: 63846.689
A26: Production Costs | B26: =sum(B27:B32) -> 528862.77 | C26: =sum(C27:C32) -> 529614.31 | D26: =sum(D27:D32) -> 529614.31 | E26: =sum(E27:E32) -> 529614.31 | F26: =sum(F27:F32) -> 552642.69 | G26: =sum(G27:G32) -> 552163.32 | H26: =sum(H27:H32) -> 1005858.5 | I26: =sum(I27:I32) -> 0
A27: Bottling lines fixed costs | B27: 50000 | C27: 50000 | D27: 50000 | E27: 50000 | F27: 50000 | G27: 50000 | H27: 92500
A28: Permanent employees | B28: 300000 | C28: 300000 | D28: 300000 | E28: 300000 | F28: 300000 | G28: 300000 | H28: 660000
A29: Flexible manpower | B29: 4206.3164 | C29: 4417.2878 | D29: 4417.2878 | E29: 4417.2878 | F29: 6704.0833 | G29: 1640.9733 | H29: 6157.6599
A30: Outsourcing | B30: 0 | C30: 0 | D30: 0 | E30: 0 | F30: 0 | G30: 0 | H30: 12.6731
A31: Mixer fixed costs | B31: 31250 | C31: 31250 | D31: 31250 | E31: 31250 | F31: 31250 | G31: 31250 | H31: 56250
A32: Mixer variable costs | B32: 143406.46 | C32: 143947.03 | D32: 143947.03 | E32: 143947.03 | F32: 164688.61 | G32: 169272.34 | H32: 190938.19
A37: Operating profit | B37: =B18-B38 -> -180777.82 | C37: =C18-C38 -> -153820.64 | D37: =D18-D38 -> -153820.64 | E37: =E18-E38 -> -153820.64 | F37: =F18-F38 -> -272024.87 | G37: =G18-G38 -> 101631.84 | H37: =H18-H38 -> -974755.9 | I37: =I18-I38 -> -170034.78
A38: Indirect Cost | B38: =sum(B39,B44,B56,B65,B74,B76,B80 ) -> 1105974.3 | C38: =sum(C39,C44,C56,C65,C74,C76,C80 ) -> 1110093.3 | D38: =sum(D39,D44,D56,D65,D74,D76,D80 ) -> 1110093.3 | E38: =sum(E39,E44,E56,E65,E74,E76,E80 ) -> 1110093.3 | F38: =sum(F39,F44,F56,F65,F74,F76,F80 ) -> 1104186.3 | G38: =sum(G39,G44,G56,G65,G74,G76,G80 ) -> 1116460.6 | H38: =sum(H39,H44,H56,H65,H74,H76,H80 ) -> 1112990.7 | I38: =sum(I39,I44,I56,I65,I74,I76,I80 ) -> 170034.78
A39: Overhead Costs | B39: =sum(B40:B42) -> 340384.9 | C39: =sum(C40:C42) -> 340986.43 | D39: =sum(D40:D42) -> 340986.43 | E39: =sum(E40:E42) -> 340986.43 | F39: =sum(F40:F42) -> 365355.46 | G39: =sum(G40:G42) -> 344365.11 | H39: =sum(H40:H42) -> 349614.19 | I39: =sum(I40:I42) -> 0
A40: Energy | B40: 151594.67 | C40: 152233.73 | D40: 152233.73 | E40: 152233.73 | F40: 154798.88 | G40: 154616.63 | H40: 147546.28
A41: Water | B41: 25230.5 | C41: 25192.973 | D41: 25192.973 | E41: 25192.973 | F41: 42578.272 | G41: 46433.786 | H41: 44817.446
A42: Other | B42: 163559.72 | C42: 163559.72 | D42: 163559.72 | E42: 163559.72 | F42: 167978.3 | G42: 143314.69 | H42: 157250.47
A44: Stock Costs | B44: =sum(B45,B48,B53 ) -> 310210.28 | C44: =sum(C45,C48,C53 ) -> 313060.45 | D44: =sum(D45,D48,D53 ) -> 313060.45 | E44: =sum(E45,E48,E53 ) -> 313060.45 | F44: =sum(F45,F48,F53 ) -> 299358.09 | G44: =sum(G45,G48,G53 ) -> 308092.9 | H44: =sum(H45,H48,H53 ) -> 287498.67 | I44: =sum(I45,I48,I53 ) -> 0
A45: Interest on stock value | B45: =sum(B46:B47) -> 24781.935 | C45: =sum(C46:C47) -> 25279.511 | D45: =sum(D46:D47) -> 25279.511 | E45: =sum(E46:E47) -> 25279.511 | F45: =sum(F46:F47) -> 13382.976 | G45: =sum(G46:G47) -> 22527.946 | H45: =sum(H46:H47) -> 19529.879
A46: Interest components | B46: 12432.959 | C46: 12665.811 | D46: 12665.811 | E46: 12665.811 | F46: 7119.1799 | G46: 8804.7321 | H46: 6082.9064
A47: Interest products | B47: 12348.976 | C47: 12613.699 | D47: 12613.699 | E47: 12613.699 | F47: 6263.7965 | G47: 13723.213 | H47: 13446.973
A48: Space | B48: =sum(B49:B52) -> 255409.74 | C48: =sum(C49:C52) -> 256107.4 | D48: =sum(D49:D52) -> 256107.4 | E48: =sum(E49:E52) -> 256107.4 | F48: =sum(F49:F52) -> 248000 | G48: =sum(G49:G52) -> 248000 | H48: =sum(H49:H52) -> 248000
A49: Pallet locations raw materials warehouse | B49: 90000 | C49: 90000 | D49: 90000 | E49: 90000 | F49: 90000 | G49: 90000 | H49: 90000
A50: Overflow raw materials warehouse | B50: 7409.7389 | C50: 8107.4046 | D50: 8107.4046 | E50: 8107.4046 | F50: 0 | G50: 0 | H50: 0
A51: Tank yard | B51: 8000 | C51: 8000 | D51: 8000 | E51: 8000 | F51: 8000 | G51: 8000 | H51: 8000
...

Sheet BOM
A1: COMPONENT | J1: FINISHED GOOD | R1: BOTTLING | Z1: MIXING
A3: FG SKU | B3: Pack 1L | C3: PET | D3: Orange | E3: Mango | F3: Vitamin C | G3: Water | H3: Type of Container | J3: FG SKU | K3: Shelf life in weeks | L3: Number per outer box | M3: Number per pallet layer | N3: Number per pallet | O3: Liters per pack | P3: Sales price (retail) | R3: Bottling type line | S3: Swiss fill 1 | T3: Top speed 1 | U3: Multi Flex 1 | W3: Number of shifts | X3: Working hours | Z3: Mixer type | AA3: Fruitmix MQ | AB3: Megachum 20 | AC3: FMM 4000
A4: Fressie Orange 1 liter | B4: 1 | D4: 0.2 | G4: 0.8 | H4: Pack 1L | J4: Fressie Orange 1 liter | K4: 20 | L4: 10 | M4: 120 | N4: 600 | O4: 1 | P4: 0.5 | R4: Capacity (liters per hour) | S4: 2800 | T4: 3000 | U4: 2500 | W4: 1 | X4: 40 | Z4: Technical batch minimum (in litters) | AA4: 8000 | AB4: 15000 | AC4: 3000
A5: Fressie Orange/Mango 1 liter | B5: 1 | D5: 0.15 | E5: 0.05 | G5: 0.8 | H5: Pack 1L | J5: Fressie Orange/Mango 1 liter | K5: 20 | L5: 10 | M5: 120 | N5: 600 | O5: 1 | P5: 0.52 | R5: Number of Operators | S5: 5 | T5: 4 | U5: 6 | W5: 2 | X5: 80 | Z5: Maximum lot size (in litters) | AA5: 12000 | AB5: 20000 | AC5: 6000
A6: Fressie Orange/Mango+C 1L | B6: 1 | D6: 0.14 | E6: 0.05 | F6: 0.01 | G6: 0.8 | H6: Pack 1L | J6: Fressie Orange/Mango+C 1L | K6: 20 | L6: 10 | M6: 120 | N6: 600 | O6: 1 | P6: 0.6 | R6: _x0008_Operators cost per annum | S6: 40000 | T6: 40000 | U6: 40000 | W6: 3 | X6: 120 | Z6: Yearly cost | AA6: 62500 | AB6: 75000 | AC6: 50000
A7: Fressie Orange PET | C7: 1 | D7: 0.06 | G7: 0.24 | H7: PET | J7: Fressie Orange PET | K7: 20 | L7: 48 | M7: 576 | N7: 2880 | O7: 0.3 | P7: 0.24 | R7: Costs flexible per hour | S7: 42 | T7: 42 | U7: 42 | W7: 4 | X7: 144 | Z7: Mixer costs per hour | AA7: 135 | AB7: 160 | AC7: 100
A8: Fressie Orange/C-power PET | C8: 1 | D8: 0.05 | F8: 0.01 | G8: 0.24 | H8: PET | J8: Fressie Orange/C-power PET | K8: 20 | L8: 48 | M8: 576 | N8: 2880 | O8: 0.3 | P8: 0.35 | R8: Costs per annum | S8: 100000 | T8: 115000 | U8: 85000 | W8: 5 | X8: 168 | Z8: Investment | AA8: 312500 | AB8: 375000 | AC8: 250000
A9: Fressie Orange/Mango PET | C9: 1 | D9: 0.045 | E9: 0.015 | G9: 0.24 | H9: PET | J9: Fressie Orange/Mango PET | K9: 20 | L9: 48 | M9: 576 | N9: 2880 | O9: 0.3 | P9: 0.28 | R9: Investment | S9: 500000 | T9: 575000 | U9: 425000 | Z9: Run time per batch (in hours) | AA9: 2 | AB9: 2 | AC9: 2
R10: Formular changeover time (in hours) | S10: 2 | T10: 3 | U10: 1 | Z10: Cleanning time (in hours) | AA10: 2 | AB10: 3 | AC10: 1
A11: CPT SKU | B11: Shelf life in weeks | C11: Pallet layer content | D11: Pallet content | E11: Basic price | R11: Size changeover time (in hours) | S11: 3 | T11: 4 | U11: 2 | Z11: Minimum batch per date | AA11: 2 | AB11: 3 | AC11: 2
A12: Pack 1L | B12: - | C12: - | D12: 20000 | E12: 0.025 | R12: Tolerances | S12: _x0008_Middle | T12: Narrow | U12: Wide | Z12: Maximum batch per date | AA12: 4 | AB12: 4 | AC12: 4
A13: PET | B13: - | C13: 288 | D13: 1440 | E13: 0.03 | R13: _x0008_Start up productivity loss | S13: 0.1 | T13: 0.15 | U13: 0.08
A14: Orange | B14: 52 | C14: - | D14: - | E14: 0.45
A15: Mango | B15: 52 | C15: - | D15: - | E15: 1.1
A16: Vitamin C | B16: 52 | C16: - | D16: - | E16: 4
A18: _x0008_CONTAINER | B18: Liter
A19: Content drum (liter) | B19: 250
A20: Content IBC (liter) | B20: 1000
A21: Content tank truck (liter) | B21: 30000
A22: Pallets per FTL | B22: 30

Sheet Demand
A1: ROUND 1 | B1: Fressie Orange 1 liter | C1: 68.429 | F1: DEMAND | G1: Pack | H1: PET | I1: Orange | J1: Mango | K1: Vitamin C
B2: Fressie Orange/Mango 1 liter | C2: 11.385 | F2: ROUND 1 | G2: 133740 | H2: 205236 | I2: 34559 | J2: 3821 | K2: 683
B3: Fressie Orange/Mango+C 1L | C3: 42.857 | F3: ROUND 2 | G3: 135540 | H3: 210679 | I3: 35170 | J3: 3881 | K3: 697
B4: Fressie Orange PET | C4: 117.495 | F4: ROUND 3 | G4: 136333 | H4: 207615 | I4: 35215 | J4: 3837 | K4: 672
B5: Fressie Orange/C-power PET | C5: 18.456 | F5: ROUND 4 | G5: 130489 | H5: 196949 | I5: 33598 | J5: 3665 | K5: 651
B6: Fressie Orange/Mango PET | C6: 52.058 | F6: ROUND 5
A7: ROUND 2 | B7: Fressie Orange 1 liter | C7: 68.429 | F7: Predict
B8: Fressie Orange/Mango 1 liter | C8: 11.385
B9: Fressie Orange/Mango+C 1L | C9: 42.857
B10: Fressie Orange PET | C10: 117.495
B11: Fressie Orange/C-power PET | C11: 18.456
B12: Fressie Orange/Mango PET | C12: 52.058
A13: ROUND 3 | B13: Fressie Orange 1 liter | C13: 68.429
B14: Fressie Orange/Mango 1 liter | C14: 11.385
B15: Fressie Orange/Mango+C 1L | C15: 42.857
B16: Fressie Orange PET | C16: 117.494
B17: Fressie Orange/C-power PET | C17: 18.454
B18: Fressie Orange/Mango PET | C18: 52.057
A19: ROUND 4 | B19: Fressie Orange 1 liter | C19: 68429
B20: Fressie Orange/Mango 1 liter | C20: 11385
B21: Fressie Orange/Mango+C 1L | C21: 42857
B22: Fressie Orange PET | C22: 117494
B23: Fressie Orange/C-power PET | C23: 18454
B24: Fressie Orange/Mango PET | C24: 52057
A25: ROUND 5 | B25: Fressie Orange 1 liter | E25: 68.429
B26: Fressie Orange/Mango 1 liter | E26: 11.385
B27: Fressie Orange/Mango+C 1L | D27: ? | E27: 42.857
B28: Fressie Orange PET | E28: 117.495
B29: Fressie Orange/C-power PET | E29: 18.456
B30: Fressie Orange/Mango PET | E30: 52.058

Sheet Inbound
A1: INBOUND TUTORIAL
A2: Fomular: Average Palet Localtion = (Qmin + Qmax)/2 = Safety Stock + Order Size/2
G3: Mark-up 37%
A4: FG SKU | B4: Type of Container | C4: Demand (pcs) | D4: % Obsolete | E4: Total demand | F4: Safety Stock (Week) | G4: Lot Size (Week) | H4: Projection Order size - Lot size (Week) | I4: Purchases | J4: Safety Stock (pcs) | K4: Order Size (pcs) | L4: _x0008_Average Demand (pcs)
A5: Fressie Orange 1 liter | B5: =VLOOKUP(A5,BOM!$A:$H,8,0) -> Pack 1L | C5: =Demand!C19 -> 68429 | D5: 0.129 | E5: =C5*(1+D5) -> 77256.341 | F5: 2.5 | G5: 2 | H5: =G5 -> 2 | I5: =26/H5 -> 13 | J5: =$E5*F5 -> 193140.85 | K5: =$C5*26/I5 -> 136858 | L5: =J5+K5/2 -> 261569.85
A6: Fressie Orange/Mango 1 liter | B6: =VLOOKUP(A6,BOM!$A:$H,8,0) -> Pack 1L | C6: =Demand!C20 -> 11385 | D6: 0.122 | E6: =C6*(1+D6) -> 12773.97 | F6: 3 | G6: 2 | H6: =G6 -> 2 | I6: =26/H6 -> 13 | J6: =$E6*F6 -> 38321.91 | K6: =$C6*26/I6 -> 22770 | L6: =J6+K6/2 -> 49706.91
A7: Fressie Orange/Mango+C 1L | B7: =VLOOKUP(A7,BOM!$A:$H,8,0) -> Pack 1L | C7: =Demand!C21 -> 42857 | D7: 0.07 | E7: =C7*(1+D7) -> 45856.99 | F7: 2 | G7: 2 | H7: =G7 -> 2 | I7: =26/H7 -> 13 | J7: =$E7*F7 -> 91713.98 | K7: =$C7*26/I7 -> 85714 | L7: =J7+K7/2 -> 134570.98
A8: Fressie Orange PET | B8: =VLOOKUP(A8,BOM!$A:$H,8,0) -> PET | C8: =Demand!C22 -> 117494 | D8: 0.063 | E8: =C8*(1+D8) -> 124896.12 | F8: 2 | G8: 2 | H8: =G8 -> 2 | I8: =26/H8 -> 13 | J8: =$E8*F8 -> 249792.24 | K8: =$C8*26/I8 -> 234988 | L8: =J8+K8/2 -> 367286.24
A9: Fressie Orange/C-power PET | B9: =VLOOKUP(A9,BOM!$A:$H,8,0) -> PET | C9: =Demand!C23 -> 18454 | D9: 0.088 | E9: =C9*(1+D9) -> 20077.952 | F9: 2.5 | G9: 2 | H9: =G9 -> 2 | I9: =26/H9 -> 13 | J9: =$E9*F9 -> 50194.88 | K9: =$C9*26/I9 -> 36908 | L9: =J9+K9/2 -> 68648.88
A10: Fressie Orange/Mango PET | B10: =VLOOKUP(A10,BOM!$A:$H,8,0) -> PET | C10: =Demand!C24 -> 52057 | D10: 0.117 | E10: =C10*(1+D10) -> 58147.669 | F10: 2.5 | G10: 2 | H10: =G10 -> 2 | I10: =26/H10 -> 13 | J10: =$E10*F10 -> 145369.17 | K10: =$C10*26/I10 -> 104114 | L10: =J10+K10/2 -> 197426.17
A12: Total CPT Demand | C12: Demand per Week (pcs) | D12: Safety Stock (Week) | E12: Lot Size (Week) | F12: Projection Order size (Week) | G12: Purchases | H12: Safety Stock (pcs) | I12: Order Size (pcs) | J12: Average Demand (pcs) | K12: Pallet content | L12: Pallet location | M12: MAX PALLET LOCATION
A13: CPT SKU | B13: Pack 1L | C13: =SUMIFS($E$5:$E$10,$B$5:$B$10,$B13) -> 135887.3 | D13: 1.5 | E13: 2 | F13: =E13 -> 2 | G13: =26/F13 -> 13 | H13: =$C13*D13 -> 203830.95 | I13: =C13*E13 -> 271774.6 | J13: =H13+I13/2 -> 339718.25 | K13: =VLOOKUP(B13,BOM!A:H,4,0) -> 20000 | L13: =J13/K13 -> 16.985913 | M13: =(H13+I13)/K13 -> 23.780278 | O13: Pallet Location | P13: Tank
B14: PET | C14: =SUMIFS($E$5:$E$10,$B$5:$B$10,$B14) -> 203121.74 | D14: 2 | E14: 2.9 | F14: =E14 -> 2.9 | G14: =26/F14 -> 8.9655172 | H14: =$C14*D14 -> 406243.49 | I14: =C14*E14 -> 589053.05 | J14: =H14+I14/2 -> 700770.01 | K14: =VLOOKUP(B14,BOM!A:H,4,0) -> 1440 | L14: =J14/K14 -> 486.64584 | M14: =(H14+I14)/K14 -> 691.17815 | O14: Pack | P14: Trade Unit Tank
O15: PET
B16: Average Need | C16: Tolerance (20%) | D16: Max Need | E16: Tolerance (20%) | I16: Tính lot size ( đây là theo week thực tế ) | O16: IBCs
A17: Total Pallet Location | B17: =SUM(L13:L14) -> 503.63176 | C17: =B17*1.2 -> 604.35811 | D17: =sum(M13:M14) -> 714.95843 | E17: =D17*1.2 -> 857.95012 | O17: Drums
A20: FG SKU | B20: Demand (pcs) | C20: Orange | D20: Mango | E20: Vitamin C | F20: Orange (liter) | G20: Mango (liter) | H20: Vitamin C (liter)
A21: =A5 -> Fressie Orange 1 liter | B21: =C5 -> 68429 | C21: =VLOOKUP($A21,BOM!$A:$H,4,0) -> 0.2 | D21: =VLOOKUP($A21,BOM!$A:$H,5,0) | E21: =VLOOKUP($A21,BOM!$A:$H,6,0) | F21: =$B21*C21 -> 13685.8 | G21: =$B21*D21 -> 0 | H21: =$B21*E21 -> 0
A22: =A6 -> Fressie Orange/Mango 1 liter | B22: =C6 -> 11385 | C22: =VLOOKUP($A22,BOM!$A:$H,4,0) -> 0.15 | D22: =VLOOKUP($A22,BOM!$A:$H,5,0) -> 0.05 | E22: =VLOOKUP($A22,BOM!$A:$H,6,0) | F22: =$B22*C22 -> 1707.75 | G22: =$B22*D22 -> 569.25 | H22: =$B22*E22 -> 0
A23: =A7 -> Fressie Orange/Mango+C 1L | B23: =C7 -> 42857 | C23: =VLOOKUP($A23,BOM!$A:$H,4,0) -> 0.14 | D23: =VLOOKUP($A23,BOM!$A:$H,5,0) -> 0.05 | E23: =VLOOKUP($A23,BOM!$A:$H,6,0) -> 0.01 | F23: =$B23*C23 -> 5999.98 | G23: =$B23*D23 -> 2142.85 | H23: =$B23*E23 -> 428.57
A24: =A8 -> Fressie Orange PET | B24: =C8 -> 117494 | C24: =VLOOKUP($A24,BOM!$A:$H,4,0) -> 0.06 | D24: =VLOOKUP($A24,BOM!$A:$H,5,0) | E24: =VLOOKUP($A24,BOM!$A:$H,6,0) | F24: =$B24*C24 -> 7049.64 | G24: =$B24*D24 -> 0 | H24: =$B24*E24 -> 0
A25: =A9 -> Fressie Orange/C-power PET | B25: =C9 -> 18454 | C25: =VLOOKUP($A25,BOM!$A:$H,4,0) -> 0.05 | D25: =VLOOKUP($A25,BOM!$A:$H,5,0) | E25: =VLOOKUP($A25,BOM!$A:$H,6,0) -> 0.01 | F25: =$B25*C25 -> 922.7 | G25: =$B25*D25 -> 0 | H25: =$B25*E25 -> 184.54
A26: =A10 -> Fressie Orange/Mango PET | B26: =C10 -> 52057 | C26: =VLOOKUP($A26,BOM!$A:$H,4,0) -> 0.045 | D26: =VLOOKUP($A26,BOM!$A:$H,5,0) -> 0.015 | E26: =VLOOKUP($A26,BOM!$A:$H,6,0) | F26: =$B26*C26 -> 2342.565 | G26: =$B26*D26 -> 780.855 | H26: =$B26*E26 -> 0
A28: Total CPT Demand | C28: Demand (liter) | D28: Safety Stock (Week) | E28: Lot Size (Week) | F28: Projection Order size (Week) | G28: Purchases | H28: Safety Stock (liter) | I28: Order Size (liter) | J28: _x0008_Average Demand (liter) | K28: Container | L28: Tank/Drum/IBC content | M28: Tank/Drum/IBC location | N28: Max Tank/Drum/IBC location
A29: CPT SKU | B29: Orange | C29: =SUM(F21:F26) -> 31708.435 | D29: 3 | E29: 1.8 | F29: =E29 -> 1.8 | G29: =26/F29 -> 14.444444 | H29: =C29*D29 -> 95125.305 | I29: =C29*26/G29 -> 57075.183 | J29: =H29+I29/2 -> 123662.9 | K29: Content tank truck (liter) | L29: =VLOOKUP(K29,BOM!A:B,2,0) -> 30000 | M29: =J29/L29 -> 4.1220966 | N29: =(H29+I29)/L29 -> 5.0733496
B30: Mango | C30: =SUM(G21:G26) -> 3492.955 | D30: 3 | E30: 1 | F30: =E30 -> 1 | G30: =26/F30 -> 26 | H30: =C30*D30 -> 10478.865 | I30: =C30*26/G30 -> 3492.955 | J30: =H30+I30/2 -> 12225.343 | K30: Content tank truck (liter) | L30: =VLOOKUP(K30,BOM!A:B,2,0) -> 30000 | M30: =J30/L30 -> 0.40751142 | N30: =(H30+I30)/L30 -> 0.46572733
B31: Vitamin C | C31: =SUM(H21:H26) -> 613.11 | D31: 3 | E31: 2 | F31: =E31 -> 2 | G31: =26/F31 -> 13 | H31: =C31*D31 -> 1839.33 | I31: =C31*26/G31 -> 1226.22 | J31: =H31+I31/2 -> 2452.44 | K31: Content IBC (liter) | L31: =VLOOKUP(K31,BOM!A:B,2,0) -> 1000 | M31: =J31/L31 -> 2.45244 | N31: =(H31+I31)/L31 -> 3.06555
I32: =H31+I31 -> 3065.55 | J32: =19*40 -> 760
A33: Number of Tanks | B33: 4 | D33: Number of Pallets | E33: 900
B34: Average Need | C34: Tolerance (20%) | D34: Max Need | E34: Tolerance (20%) | K34: Cái Lot Size (Week) ở đây hình như phải tính là moq ( lot size trong TFC ) / demand theo week
A35: Total Number of Tank | B35: =SUMIFS(M29:M31,K29:K31,"Content tank truck (liter)") -> 4.529608 | C35: =B35*1.2 -> 5.4355296 | D35: =SUMIFS(N29:N31,K29:K31,"Content tank truck (liter)") -> 5.5390769 | E35: =D35*1.2 -> 6.6468923
A36: Total Number of IBC | B36: =SUMIFS(M29:M31,K29:K31,"Content IBC (liter)") -> 2.45244 | C36: =B36*1.2 -> 2.942928 | D36: =SUMIFS(N29:N31,K29:K31,"Content IBC (liter)") -> 3.06555 | E36: =D36*1.2 -> 3.67866
A37: Total Number of Drum | B37: =SUMIFS(M29:M31,K29:K31,"Content drum (liter)") -> 0 | C37: =B37*1.2 -> 0 | D37: =SUMIFS(N29:N31,K29:K31,"Content drum (liter)") -> 0 | E37: =D37*1.2 -> 0
A38: Overflow IBC | B38: =(B41-B33)*30000/1000 -> 43.065887 | C38: =B38*1.2 -> 51.679064 | D38: =(D41-B33)*30000/1000 -> 79.40677 | E38: =D38*1.2 -> 95.288124
A40: Total Pallet | B40: =SUM(C17,C36:C38) -> 658.9801 | C40: Total Pallet Max | D40: =sum(E17,E36:E38) -> 956.9169
A41: Total Tank | B41: =C35 -> 5.4355296 | C41: Total Tank Max | D41: =E35 -> 6.6468923
A42: %CU of Pallets | B42: =B40/900 -> 0.73220011 | D42: %CU of Pallets Max | E42: =D40/E33 -> 1.063241
A43: %CU of Tanks | B43: =B41/B33 -> 1.3588824 | D43: %CU of Tanks Max | E43: =D41/B33 -> 1.6617231
B44: Average Working hours per week | C44: Working hours for 1 FTE per week | D44: FTE
A45: Total Number of FTE | B45: 63 | C45: 40 | D45: =B45/C45 -> 1.575

Sheet Mixing
A1: MIXING MACHINE
C2: lít/h | D2: Min | E2: Max
A3: Mixer available | B3: Decision | D3: =A7/(C7+D7) -> 2000 | E3: =B7/(C7+D7) -> 3000
A4: Mixer | B4: Fruitmix MQ
G5: Minimum batch | I5: Maximum batch
A6: Technical batch minimum (in litters) | B6: Maximum lot size (in litters) | C6: Run time per batch (in hours) | D6: Cleanning time (in hours) | E6: Minimum batch per date | F6: Maximum batch per date | G6: Technical Capacity | H6: Maximum Capacity | I6: Technical Capacity | J6: Maximum Capacity
A7: =IF(B4=BOM!AA3,VLOOKUP(A6,BOM!Z:AC,2,0),IF(B4=BOM!AB3,VLOOKUP(A6,BOM!Z:AC,3,0),VLOOKUP(A6,BOM!Z:AC,4,0))) -> 8000 | B7: =IF(B4=BOM!AA3,VLOOKUP(B6,BOM!Z:AC,2,0),IF(B4=BOM!AB3,VLOOKUP(B6,BOM!Z:AC,3,0),VLOOKUP(B6,BOM!Z:AC,4,0))) -> 12000 | C7: =IF(B4=BOM!AA3,VLOOKUP(C6,BOM!Z:AC,2,0),IF(B4=BOM!AB3,VLOOKUP(C6,BOM!Z:AC,3,0),VLOOKUP(C6,BOM!Z:AC,4,0))) -> 2 | D7: =IF(B4=BOM!AA3,VLOOKUP(D6,BOM!Z:AC,2,0),IF(B4=BOM!AB3,VLOOKUP(D6,BOM!Z:AC,3,0),VLOOKUP(D6,BOM!Z:AC,4,0))) -> 2 | E7: =IF(B4=BOM!AA3,VLOOKUP(E6,BOM!Z:AC,2,0),IF(B4=BOM!AB3,VLOOKUP(E6,BOM!Z:AC,3,0),VLOOKUP(E6,BOM!Z:AC,4,0))) -> 2 | F7: =IF(B4=BOM!AA3,VLOOKUP(F6,BOM!Z:AC,2,0),IF(B4=BOM!AB3,VLOOKUP(F6,BOM!Z:AC,3,0),VLOOKUP(F6,BOM!Z:AC,4,0))) -> 4 | G7: =A7*$E$7 -> 16000 | H7: =B7*$E$7 -> 24000 | I7: =A7*$F$7 -> 32000 | J7: =B7*$F$7 -> 48000
A9: Cleanning time (%) | B9: Operation time (%) | C9: Cleanning time (hour) | D9: Operation time (hour) | E9: Technical Capacity | F9: Maximum Capacity
A10: 0.191 | B10: =1-A10 -> 0.809 | C10: =40*A10 -> 7.64 | D10: =40*B10 -> 32.36 | E10: =$D$10/$C$7*A7 -> 129440 | F10: =$D$10/$C$7*B7 -> 194160
I12: Master Production Schedule
A13: FG SKU | B13: Demand (pcs) | C13: Interval Production | D13: Batch | E13: Q Production (pcs) | F13: Adherence | G13: Liters per pack | H13: Q Production (litter) | I13: W1 | J13: W2 | K13: W3 | L13: W4 | M13: W5 | N13: W6 | O13: W7 | P13: W8 | Q13: W9 | R13: W10 | S13: W11 | T13: W12 | U13: W13 | V13: W14 | W13: W15 | X13: W16 | Y13: W17 | Z13: W18 | AA13: W19 | AB13: W20 | AC13: W21 | AD13: W22 | AE13: W23 | AF13: W24 | AG13: W25 | AH13: W26 | AI13: Grand Total
A14: =Inbound!A5 -> Fressie Orange 1 liter | B14: =Inbound!C5 -> 68429 | C14: 5 | D14: =26/(C14/5) -> 26 | E14: =B14*26/D14 -> 68429 | F14: 1 | G14: =BOM!O4 -> 1 | H14: =E14*F14*G14 -> 68429 | I14: 68429 | J14: 68429 | K14: 68429 | L14: 68429 | M14: 68429 | N14: 68429 | O14: 68429 | P14: 68429 | Q14: 68429 | R14: 68429 | S14: 68429 | T14: 68429 | U14: 68429 | V14: 68429 | W14: 68429 | X14: 68429 | Y14: 68429 | Z14: 68429 | AA14: 68429 | AB14: 68429 | AC14: 68429 | AD14: 68429 | AE14: 68429 | AF14: 68429 | AG14: 68429 | AH14: 68429 | AI14: =SUM(I14:AH14) -> 1779154
A15: =Inbound!A6 -> Fressie Orange/Mango 1 liter | B15: =Inbound!B22 -> 11385 | C15: 5 | D15: =26/(C15/5) -> 26 | E15: =B15*26/D15 -> 11385 | F15: 1 | G15: =BOM!O5 -> 1 | H15: =E15*F15*G15 -> 11385 | I15: 11385 | J15: 11385 | K15: 11385 | L15: 11385 | M15: 11385 | N15: 11385 | O15: 11385 | P15: 11385 | Q15: 11385 | R15: 11385 | S15: 11385 | T15: 11385 | U15: 11385 | V15: 11385 | W15: 11385 | X15: 11385 | Y15: 11385 | Z15: 11385 | AA15: 11385 | AB15: 11385 | AC15: 11385 | AD15: 11385 | AE15: 11385 | AF15: 11385 | AG15: 11385 | AH15: 11385 | AI15: =SUM(I15:AH15) -> 296010
A16: =Inbound!A7 -> Fressie Orange/Mango+C 1L | B16: =Inbound!B23 -> 42857 | C16: 5 | D16: =26/(C16/5) -> 26 | E16: =B16*26/D16 -> 42857 | F16: 1 | G16: =BOM!O6 -> 1 | H16: =E16*F16*G16 -> 42857 | I16: 42857 | J16: 42857 | K16: 42857 | L16: 42857 | M16: 42857 | N16: 42857 | O16: 42857 | P16: 42857 | Q16: 42857 | R16: 42857 | S16: 42857 | T16: 42857 | U16: 42857 | V16: 42857 | W16: 42857 | X16: 42857 | Y16: 42857 | Z16: 42857 | AA16: 42857 | AB16: 42857 | AC16: 42857 | AD16: 42857 | AE16: 42857 | AF16: 42857 | AG16: 42857 | AH16: 42857 | AI16: =SUM(I16:AH16) -> 1114282
A17: =Inbound!A8 -> Fressie Orange PET | B17: =Inbound!B24 -> 117494 | C17: 5 | D17: =26/(C17/5) -> 26 | E17: =B17*26/D17 -> 117494 | F17: 1 | G17: =BOM!O7 -> 0.3 | H17: =E17*F17*G17 -> 35248.2 | I17: 35248.2 | J17: 35248.2 | K17: 35248.2 | L17: 35248.2 | M17: 35248.2 | N17: 35248.2 | O17: 35248.2 | P17: 35248.2 | Q17: 35248.2 | R17: 35248.2 | S17: 35248.2 | T17: 35248.2 | U17: 35248.2 | V17: 35248.2 | W17: 35248.2 | X17: 35248.2 | Y17: 35248.2 | Z17: 35248.2 | AA17: 35248.2 | AB17: 35248.2 | AC17: 35248.2 | AD17: 35248.2 | AE17: 35248.2 | AF17: 35248.2 | AG17: 35248.2 | AH17: 35248.2 | AI17: =SUM(I17:AH17) -> 916453.2
A18: =Inbound!A9 -> Fressie Orange/C-power PET | B18: =Inbound!B25 -> 18454 | C18: 5 | D18: =26/(C18/5) -> 26 | E18: =B18*26/D18 -> 18454 | F18: 1 | G18: =BOM!O8 -> 0.3 | H18: =E18*F18*G18 -> 5536.2 | I18: 5536.2 | J18: 5536.2 | K18: 5536.2 | L18: 5536.2 | M18: 5536.2 | N18: 5536.2 | O18: 5536.2 | P18: 5536.2 | Q18: 5536.2 | R18: 5536.2 | S18: 5536.2 | T18: 5536.2 | U18: 5536.2 | V18: 5536.2 | W18: 5536.2 | X18: 5536.2 | Y18: 5536.2 | Z18: 5536.2 | AA18: 5536.2 | AB18: 5536.2 | AC18: 5536.2 | AD18: 5536.2 | AE18: 5536.2 | AF18: 5536.2 | AG18: 5536.2 | AH18: 5536.2 | AI18: =SUM(I18:AH18) -> 143941.2
A19: =Inbound!A10 -> Fressie Orange/Mango PET | B19: =Inbound!B26 -> 52057 | C19: 5 | D19: =26/(C19/5) -> 26 | E19: =B19*26/D19 -> 52057 | F19: 1 | G19: =BOM!O9 -> 0.3 | H19: =E19*F19*G19 -> 15617.1 | I19: 15617.1 | J19: 15617.1 | K19: 15617.1 | L19: 15617.1 | M19: 15617.1 | N19: 15617.1 | O19: 15617.1 | P19: 15617.1 | Q19: 15617.1 | R19: 15617.1 | S19: 15617.1 | T19: 15617.1 | U19: 15617.1 | V19: 15617.1 | W19: 15617.1 | X19: 15617.1 | Y19: 15617.1 | Z19: 15617.1 | AA19: 15617.1 | AB19: 15617.1 | AC19: 15617.1 | AD19: 15617.1 | AE19: 15617.1 | AF19: 15617.1 | AG19: 15617.1 | AH19: 15617.1 | AI19: =SUM(I19:AH19) -> 406044.6
H20: =Bottling!G22 -> Start-up loss | I20: =Bottling!H22 -> 1200 | J20: =Bottling!I22 -> 1200 | K20: =Bottling!J22 -> 1200 | L20: =Bottling!K22 -> 1200 | M20: =Bottling!L22 -> 1200 | N20: =Bottling!M22 -> 1200 | O20: =Bottling!N22 -> 1200 | ... AH20: =Bottling!AG22 -> 1200 | AI20: =SUM(I20:AH20) -> 31200
H22: Total production | I22: =SUM(I14:I20) -> 180272.5 | J22: =SUM(J14:J20) -> 180272.5 | K22: =SUM(K14:K20) -> 180272.5 | L22: =SUM(L14:L20) -> 180272.5 | M22: =SUM(M14:M20) -> 180272.5 | N22: =SUM(N14:N20) -> 180272.5 | O22: =SUM(O14:O20) -> 180272.5 | P22: =SUM(P14:P20) -> 180272.5 | ... AH22: =SUM(AH14:AH20) -> 180272.5 | AI22: =SUM(I22:AH22) -> 4687085
H23: Capacity (Min) | I23: =E10 -> 129440 | J23: =I23 -> 129440 | K23: =J23 -> 129440 | L23: =K23 -> 129440 | M23: =L23 -> 129440 | N23: =M23 -> 129440 | O23: =N23 -> 129440 | P23: =O23 -> 129440 | Q23: =P23 -> 129440 | ... AH23: =AG23 -> 129440 | AI23: =SUM(I23:AH23) -> 3365440
H24: Capacity (Max) | I24: =F10 -> 194160 | J24: =I24 -> 194160 | K24: =J24 -> 194160 | L24: =K24 -> 194160 | M24: =L24 -> 194160 | N24: =M24 -> 194160 | O24: =N24 -> 194160 | P24: =O24 -> 194160 | Q24: =P24 -> 194160 | ... AH24: =AG24 -> 194160 | AI24: =SUM(I24:AH24) -> 5048160
H25: GAP | I25: =I24-I22 -> 13887.5 | J25: =J24-J22 -> 13887.5 | K25: =K24-K22 -> 13887.5 | L25: =L24-L22 -> 13887.5 | M25: =M24-M22 -> 13887.5 | N25: =N24-N22 -> 13887.5 | O25: =O24-O22 -> 13887.5 | P25: =P24-P22 -> 13887.5 | ... AH25: =AH24-AH22 -> 13887.5 | AI25: =SUM(I25:AH25) -> 361075
H26: Utilization | I26: =I22/I24 -> 0.92847394 | J26: =J22/J24 -> 0.92847394 | K26: =K22/K24 -> 0.92847394 | L26: =L22/L24 -> 0.92847394 | M26: =M22/M24 -> 0.92847394 | N26: =N22/N24 -> 0.92847394 | O26: =O22/O24 -> 0.92847394 | P26: =P22/P24 -> 0.92847394 | ... AI26: =AI22/AI24 -> 0.92847394

Sheet Bottling
F2: shift | G2: 40000
A3: Line settings | B3: Decision | C3: swiss fill | D3: top speed 1 | E3: multi flex | F3: top speed 1 | G3: multi flex | H3: swiss fill | J3: top speed 1 | K3: multi flex | L3: sswissfill
A4: Bottling line | B4: Multi Flex 1 | C4: 2 | D4: 2 | E4: 3 | F4: 115000 | G4: 85000 | H4: 100000 | J4: =F7 -> 225000 | K4: =G7 -> 205000 | L4: =H7 -> 210000
A5: Number of shifts | B5: 3 | C5: increase speed | D5: increase speed | E5: no | F5: =D4*G2 -> 80000 | G5: =E4*G2 -> 120000 | H5: =C4*G2 -> 80000 | J5: 62100 | K5: 27600
A6: Increase speed | B6: No | F6: 30000 | G6: 0 | H6: 30000 | J6: =sum(J4:J5) -> 287100 | K6: =sum(K4:K5) -> 232600
F7: =sum(F4:F6) -> 225000 | G7: =sum(G4:G6) -> 205000 | H7: =sum(H4:H6) -> 210000
A8: Capacity (liters per hour) | B8: Nominal Working hour per week | C8: Changeover time (Hour) | D8: Breakdown time (Hour) | E8: Actual Working hour per week | F8: Start up productivity loss | G8: Actual Capacity Weekly (litter)
A9: =IF(B6="yes",IF(B4=BOM!S3,VLOOKUP(A8,BOM!R3:U13,2,0)*110%,IF(B4=BOM!T3,VLOOKUP(A8,BOM!R3:U13,3,0)*110%,VLOOKUP(A8,BOM!R3:U13,4,0)*110%)),IF(B4=BOM!S3,VLOOKUP(A8,BOM!R3:U13,2,0),IF(B4=BOM!T3,VLOOKUP(A8,BOM!R3:U13,3,0),VLOOKUP(A8,BOM!R3:U13,4,0)))) -> 2500 | B9: =VLOOKUP(B5,BOM!W:X,2,0) -> 120 | C9: 10.8 | D9: 9.1 | E9: =B9-C9-D9 -> 100.1 | F9: =IF(B4="Top speed 1",15%,if(B4="Multi Flex 1",8%,0)) -> 0.08 | G9: =E9*A9 -> 250250
C11: Formular changeover time (in hours) | D11: Size changeover time (in hours)
A12: In normal | C12: =IF(B4=BOM!S3,VLOOKUP(C11,BOM!R3:U13,2,0),IF(B4=BOM!T3,VLOOKUP(C11,BOM!R3:U13,3,0),VLOOKUP(C11,BOM!R3:U13,4,0))) -> 1 | D12: =IF(B4=BOM!S3,VLOOKUP(D11,BOM!R3:U13,2,0),IF(B4=BOM!T3,VLOOKUP(D11,BOM!R3:U13,3,0),VLOOKUP(D11,BOM!R3:U13,4,0))) -> 2
A13: SMED action | B13: Yes | C13: =IF(B13="Yes",C12*70%,C12) -> 0.7 | D13: =IF(B13="Yes",D12*70%,D12) -> 1.4
G14: Volume | H14: _x0008_Master Production Schedule
A15: FG SKU | B15: Demand forecast (pcs) | C15: Interval Production | D15: Batch | E15: Batch size (pcs) | F15: Liters per pack | G15: Q Production (litter) | H15: W1 | I15: W2 | J15: W3 | K15: W4 | L15: W5 | M15: W6 | N15: W7 | O15: W8 | P15: W9 | Q15: W10 | R15: W11 | S15: W12 | T15: W13 | U15: W14 | V15: W15 | W15: W16 | X15: W17 | Y15: W18 | Z15: W19 | AA15: W20 | AB15: W21 | AC15: W22 | AD15: W23 | AE15: W24 | AF15: W25 | AG15: W26 | AH15: Grand Total
A16: =Inbound!A5 -> Fressie Orange 1 liter | B16: =Inbound!B21 -> 68429 | C16: 5 | D16: =5*26/C16 -> 26 | E16: =B16*C16/5 -> 68429 | F16: 1 | G16: =E16*F16 -> 68429 | H16: 68429 | I16: 68429 | J16: 68429 | K16: 68429 | L16: 68429 | M16: 68429 | N16: 68429 | O16: 68429 | P16: 68429 | Q16: 68429 | R16: 68429 | S16: 68429 | T16: 68429 | U16: 68429 | V16: 68429 | W16: 68429 | X16: 68429 | Y16: 68429 | Z16: 68429 | AA16: 68429 | AB16: 68429 | AC16: 68429 | AD16: 68429 | AE16: 68429 | AF16: 68429 | AG16: 68429 | AH16: =SUM(H16:AG16) -> 1779154
A17: =Inbound!A6 -> Fressie Orange/Mango 1 liter | B17: =Inbound!B22 -> 11385 | C17: =Mixing!C15 -> 5 | D17: =5*26/C17 -> 26 | E17: =B17*C17/5 -> 11385 | F17: 1 | G17: =E17*F17 -> 11385 | H17: 11385 | I17: 11385 | J17: 11385 | K17: 11385 | L17: 11385 | M17: 11385 | N17: 11385 | O17: 11385 | P17: 11385 | Q17: 11385 | R17: 11385 | S17: 11385 | T17: 11385 | U17: 11385 | V17: 11385 | W17: 11385 | X17: 11385 | Y17: 11385 | Z17: 11385 | AA17: 11385 | AB17: 11385 | AC17: 11385 | AD17: 11385 | AE17: 11385 | AF17: 11385 | AG17: 11385 | AH17: =SUM(H17:AG17) -> 296010
A18: =Inbound!A7 -> Fressie Orange/Mango+C 1L | B18: =Inbound!B23 -> 42857 | C18: 5 | D18: =5*26/C18 -> 26 | E18: =B18*C18/5 -> 42857 | F18: 1 | G18: =E18*F18 -> 42857 | H18: 42857 | I18: 42857 | J18: 42857 | K18: 42857 | L18: 42857 | M18: 42857 | N18: 42857 | O18: 42857 | P18: 42857 | Q18: 42857 | R18: 42857 | S18: 42857 | T18: 42857 | U18: 42857 | V18: 42857 | W18: 42857 | X18: 42857 | Y18: 42857 | Z18: 42857 | AA18: 42857 | AB18: 42857 | AC18: 42857 | AD18: 42857 | AE18: 42857 | AF18: 42857 | AG18: 42857 | AH18: =SUM(H18:AG18) -> 1114282
A19: =Inbound!A8 -> Fressie Orange PET | B19: =Inbound!B24 -> 117494 | C19: =Mixing!C17 -> 5 | D19: =5*26/C19 -> 26 | E19: =B19*C19/5 -> 117494 | F19: 0.3 | G19: =E19*F19 -> 35248.2 | H19: 35248.2 | I19: 35248.2 | J19: 35248.2 | K19: 35248.2 | L19: 35248.2 | M19: 35248.2 | N19: 35248.2 | O19: 35248.2 | P19: 35248.2 | Q19: 35248.2 | R19: 35248.2 | S19: 35248.2 | T19: 35248.2 | U19: 35248.2 | V19: 35248.2 | W19: 35248.2 | X19: 35248.2 | Y19: 35248.2 | Z19: 35248.2 | AA19: 35248.2 | AB19: 35248.2 | AC19: 35248.2 | AD19: 35248.2 | AE19: 35248.2 | AF19: 35248.2 | AG19: 35248.2 | AH19: =SUM(H19:AG19) -> 916453.2
A20: =Inbound!A9 -> Fressie Orange/C-power PET | B20: =Inbound!B25 -> 18454 | C20: =Mixing!C18 -> 5 | D20: =5*26/C20 -> 26 | E20: =B20*C20/5 -> 18454 | F20: 0.3 | G20: =E20*F20 -> 5536.2 | H20: 5536.2 | I20: 5536.2 | J20: 5536.2 | K20: 5536.2 | L20: 5536.2 | M20: 5536.2 | N20: 5536.2 | O20: 5536.2 | P20: 5536.2 | Q20: 5536.2 | R20: 5536.2 | S20: 5536.2 | T20: 5536.2 | U20: 5536.2 | V20: 5536.2 | W20: 5536.2 | X20: 5536.2 | Y20: 5536.2 | Z20: 5536.2 | AA20: 5536.2 | AB20: 5536.2 | AC20: 5536.2 | AD20: 5536.2 | AE20: 5536.2 | AF20: 5536.2 | AG20: 5536.2 | AH20: =SUM(H20:AG20) -> 143941.2
A21: =Inbound!A10 -> Fressie Orange/Mango PET | B21: =Inbound!B26 -> 52057 | C21: =Mixing!C19 -> 5 | D21: =5*26/C21 -> 26 | E21: =B21*C21/5 -> 52057 | F21: 0.3 | G21: =E21*F21 -> 15617.1 | H21: 15617.1 | I21: 15617.1 | J21: 15617.1 | K21: 15617.1 | L21: 15617.1 | M21: 15617.1 | N21: 15617.1 | O21: 15617.1 | P21: 15617.1 | Q21: 15617.1 | R21: 15617.1 | S21: 15617.1 | T21: 15617.1 | U21: 15617.1 | V21: 15617.1 | W21: 15617.1 | X21: 15617.1 | Y21: 15617.1 | Z21: 15617.1 | AA21: 15617.1 | AB21: 15617.1 | AC21: 15617.1 | AD21: 15617.1 | AE21: 15617.1 | AF21: 15617.1 | AG21: 15617.1 | AH21: =SUM(H21:AG21) -> 406044.6
G22: Start-up loss | H22: =$A$9*$F$9*COUNT(H16:H21) -> 1200 | I22: =$A$9*$F$9*COUNT(I16:I21) -> 1200 | J22: =$A$9*$F$9*COUNT(J16:J21) -> 1200 | K22: =$A$9*$F$9*COUNT(K16:K21) -> 1200 | L22: =$A$9*$F$9*COUNT(L16:L21) -> 1200 | M22: =$A$9*$F$9*COUNT(M16:M21) -> 1200 | N22: =$A$9*$F$9*COUNT(N16:N21) -> 1200 | O22: =$A$9*$F$9*COUNT(O16:O21) -> 1200 | ... AG22: =$A$9*$F$9*COUNT(AG16:AG21) -> 1200 | AH22: =SUM(H22:AG22) -> 31200
G24: Total production (Usage) | H24: =SUM(H16:H22) -> 180272.5 | I24: =SUM(I16:I22) -> 180272.5 | J24: =SUM(J16:J22) -> 180272.5 | K24: =SUM(K16:K22) -> 180272.5 | L24: =SUM(L16:L22) -> 180272.5 | M24: =SUM(M16:M22) -> 180272.5 | N24: =SUM(N16:N22) -> 180272.5 | O24: =SUM(O16:O22) -> 180272.5 | ... AH24: =SUM(AH16:AH22) -> 4687085
G25: Capacity | H25: =G9 -> 250250 | I25: =H25 -> 250250 | J25: =I25 -> 250250 | K25: =J25 -> 250250 | L25: =K25 -> 250250 | M25: =L25 -> 250250 | N25: =M25 -> 250250 | O25: =N25 -> 250250 | P25: =O25 -> 250250 | ... AG25: =AF25 -> 250250 | AH25: =SUM(H25:AG25) -> 6506500
G26: GAP | H26: =H25-H24 -> 69977.5 | I26: =I25-I24 -> 69977.5 | J26: =J25-J24 -> 69977.5 | K26: =K25-K24 -> 69977.5 | L26: =L25-L24 -> 69977.5 | M26: =M25-M24 -> 69977.5 | N26: =N25-N24 -> 69977.5 | O26: =O25-O24 -> 69977.5 | ... AG26: =AG25-AG24 -> 69977.5 | AH26: =SUM(H26:AG26) -> 1819415
G27: Utilization (%CU) | H27: =H24/H25 -> 0.72036963 | I27: =I24/I25 -> 0.72036963 | J27: =J24/J25 -> 0.72036963 | K27: =K24/K25 -> 0.72036963 | L27: =L24/L25 -> 0.72036963 | M27: =M24/M25 -> 0.72036963 | N27: =N24/N25 -> 0.72036963 | O27: =O24/O25 -> 0.72036963 | ... AH27: =AH24/AH25 -> 0.72036963

Sheet Outbound
A1: OUTBOUND TUTORIAL
A2: Fomular: Average Palet Localtion = (Qmin + Qmax)/2 = Safety Stock + Order Size/2
A4: FG SKU | B4: Demand/week (pcs) | C4: Safety Stock (Week) | D4: Production Interval (Day) | E4: %Obsolete | F4: Safety Stock (pcs) | G4: Batch Size - Production Interval (pcs) | H4: Average stock (pcs) | I4: Number per pallet | J4: Pallet location
A5: Fressie Orange 1 liter | B5: =Inbound!B21 -> 68429 | C5: 2.5 | D5: =Mixing!C14 -> 5 | E5: 0.125 | F5: =B5*C5 -> 171072.5 | G5: =B5*D5/5 -> 68429 | H5: =F5+G5/2 -> 205287 | I5: =BOM!N4 -> 600 | J5: =H5/I5 -> 342.145
A6: Fressie Orange/Mango 1 liter | B6: =Inbound!B22 -> 11385 | C6: 3 | D6: =Mixing!C15 -> 5 | E6: 0.128 | F6: =B6*C6 -> 34155 | G6: =B6*D6/5 -> 11385 | H6: =F6+G6/2 -> 39847.5 | I6: =BOM!N5 -> 600 | J6: =H6/I6 -> 66.4125
A7: Fressie Orange/Mango+C 1L | B7: =Inbound!B23 -> 42857 | C7: 2 | D7: =Mixing!C16 -> 5 | E7: 0.056 | F7: =B7*C7 -> 85714 | G7: =B7*D7/5 -> 42857 | H7: =F7+G7/2 -> 107142.5 | I7: =BOM!N6 -> 600 | J7: =H7/I7 -> 178.57083
A8: Fressie Orange PET | B8: =Inbound!B24 -> 117494 | C8: 2 | D8: =Mixing!C17 -> 5 | E8: 0.071 | F8: =B8*C8 -> 234988 | G8: =B8*D8/5 -> 117494 | H8: =F8+G8/2 -> 293735 | I8: =BOM!N7 -> 2880 | J8: =H8/I8 -> 101.99132
A9: Fressie Orange/C-power PET | B9: =Inbound!B25 -> 18454 | C9: 2.5 | D9: =Mixing!C18 -> 5 | E9: 0.112 | F9: =B9*C9 -> 46135 | G9: =B9*D9/5 -> 18454 | H9: =F9+G9/2 -> 55362 | I9: =BOM!N8 -> 2880 | J9: =H9/I9 -> 19.222917
A10: Fressie Orange/Mango PET | B10: =Inbound!B26 -> 52057 | C10: 2.5 | D10: =Mixing!C19 -> 5 | E10: 0.126 | F10: =B10*C10 -> 130142.5 | G10: =B10*D10/5 -> 52057 | H10: =F10+G10/2 -> 156171 | I10: =BOM!N9 -> 2880 | J10: =H10/I10 -> 54.226042
B13: Average Need | C13: Tolerance (20%)
A14: Total Pallet Location | B14: =SUM(J5:J10) -> 762.56861 | C14: =B14*1.2 -> 915.08233
B18: Average Working hours per week | C18: Working hours for 1 FTE per week | D18: FTE
A19: Total Number of FTE | B19: 88 | C19: 40 | D19: =B19/C19 -> 2.2

Sheet MRP
A1: FG SKU | B1: W1 | C1: W2 | D1: W3 | E1: W4 | F1: W5 | G1: W6 | H1: W7 | I1: W8 | J1: W9 | K1: W10 | L1: W11 | M1: W12 | N1: W13 | O1: W14 | P1: W15 | Q1: W16 | R1: W17 | S1: W18 | T1: W19 | U1: W20 | V1: W21 | W1: W22 | X1: W23 | Y1: W24 | Z1: W25 | AA1: W26 | AB1: Grand Total
A2: Fressie Orange PET | B2: 68429 | C2: 68429 | D2: 68429 | E2: 68429 | F2: 68429 | G2: 68429 | H2: 68429 | I2: 68429 | J2: 68429 | K2: 68429 | L2: 68429 | M2: 68429 | N2: 68429 | O2: 68429 | P2: 68429 | Q2: 68429 | R2: 68429 | S2: 68429 | T2: 68429 | U2: 68429 | V2: 68429 | W2: 68429 | X2: 68429 | Y2: 68429 | Z2: 68429 | AA2: 68429 | AB2: =SUM(B2:AA2) -> 1779154
A3: Fressie Orange/C-power PET | B3: 11385 | C3: 11385 | D3: 11385 | E3: 11385 | F3: 11385 | G3: 11385 | H3: 11385 | I3: 11385 | J3: 11385 | K3: 11385 | L3: 11385 | M3: 11385 | N3: 11385 | O3: 11385 | P3: 11385 | Q3: 11385 | R3: 11385 | S3: 11385 | T3: 11385 | U3: 11385 | V3: 11385 | W3: 11385 | X3: 11385 | Y3: 11385 | Z3: 11385 | AA3: 11385 | AB3: =SUM(B3:AA3) -> 296010
A4: Fressie Orange/Mango PET | B4: 42857 | C4: 42857 | D4: 42857 | E4: 42857 | F4: 42857 | G4: 42857 | H4: 42857 | I4: 42857 | J4: 42857 | K4: 42857 | L4: 42857 | M4: 42857 | N4: 42857 | O4: 42857 | P4: 42857 | Q4: 42857 | R4: 42857 | S4: 42857 | T4: 42857 | U4: 42857 | V4: 42857 | W4: 42857 | X4: 42857 | Y4: 42857 | Z4: 42857 | AA4: 42857 | AB4: =SUM(B4:AA4) -> 1114282
A5: Fressie Orange 1 liter | B5: 35248.2 | C5: 35248.2 | D5: 35248.2 | E5: 35248.2 | F5: 35248.2 | G5: 35248.2 | H5: 35248.2 | I5: 35248.2 | J5: 35248.2 | K5: 35248.2 | L5: 35248.2 | M5: 35248.2 | N5: 35248.2 | O5: 35248.2 | P5: 35248.2 | Q5: 35248.2 | R5: 35248.2 | S5: 35248.2 | T5: 35248.2 | U5: 35248.2 | V5: 35248.2 | W5: 35248.2 | X5: 35248.2 | Y5: 35248.2 | Z5: 35248.2 | AA5: 35248.2 | AB5: =SUM(B5:AA5) -> 916453.2
A6: Fressie Orange/Mango 1 liter | B6: 5536.2 | C6: 5536.2 | D6: 5536.2 | E6: 5536.2 | F6: 5536.2 | G6: 5536.2 | H6: 5536.2 | I6: 5536.2 | J6: 5536.2 | K6: 5536.2 | L6: 5536.2 | M6: 5536.2 | N6: 5536.2 | O6: 5536.2 | P6: 5536.2 | Q6: 5536.2 | R6: 5536.2 | S6: 5536.2 | T6: 5536.2 | U6: 5536.2 | V6: 5536.2 | W6: 5536.2 | X6: 5536.2 | Y6: 5536.2 | Z6: 5536.2 | AA6: 5536.2 | AB6: =SUM(B6:AA6) -> 143941.2
A7: Fressie Orange/Mango+C 1L | B7: 15617.1 | C7: 15617.1 | D7: 15617.1 | E7: 15617.1 | F7: 15617.1 | G7: 15617.1 | H7: 15617.1 | I7: 15617.1 | J7: 15617.1 | K7: 15617.1 | L7: 15617.1 | M7: 15617.1 | N7: 15617.1 | O7: 15617.1 | P7: 15617.1 | Q7: 15617.1 | R7: 15617.1 | S7: 15617.1 | T7: 15617.1 | U7: 15617.1 | V7: 15617.1 | W7: 15617.1 | X7: 15617.1 | Y7: 15617.1 | Z7: 15617.1 | AA7: 15617.1 | AB7: =SUM(B7:AA7) -> 406044.6
B8: =sum(B2:B7) -> 179072.5
A9: FG SKU | B9: Pack 1L | C9: PET | D9: Orange | E9: Mango | F9: Vitamin C | J9: Orange | K9: Mango | L9: Vitamin C
A10: Fressie Orange PET | C10: 1 | D10: 0.06 | H10: Lead-time | I10: 2 weeks | J10: 5.7 | K10: 4.2 | L10: 6.4
A11: Fressie Orange/C-power PET | C11: 1 | D11: 0.05 | F11: 0.01 | H11: Lotsize | I11: 2 tanks=60000lit | J11: 1 | K11: 1 | L11: 2 | M11: week | N11: 1 lần order min là 30000
A12: Fressie Orange/Mango PET | C12: 1 | D12: 0.045 | E12: 0.015 | H12: SS | I12: 2 weeks | J12: 2 | K12: 2.5 | L12: 2.5
A13: Fressie Orange 1 liter | B13: 1 | D13: 0.2 | H13: Average Inventory | I13: SS+LS/2 | J13: =J12+J11/2 -> 2.5 | K13: =K12+K11/2 -> 3 | L13: =L12+L11/2 -> 3.5 | M13: Average Inventory = Place order
A14: Fressie Orange/Mango 1 liter | B14: 1 | D14: 0.15 | E14: 0.05
A15: Fressie Orange/Mango+C 1L | B15: 1 | D15: 0.14 | E15: 0.05 | F15: 0.01 | H15: lotsize = số lượng định đặt ( mấy lotsize, như bên trên moq là 30000 liter ) / demand fc
A17: Orange (Litter) | B17: W1 | C17: W2 | D17: W3 | E17: W4 | F17: W5 | G17: W6 | H17: W7 | I17: W8 | J17: W9 | K17: W10 | L17: W11 | M17: W12 | N17: W13 | O17: W14 | P17: W15 | Q17: W16 | R17: W17 | S17: W18 | T17: W19 | U17: W20 | V17: W21 | W17: W22 | X17: W23 | Y17: W24 | Z17: W25 | AA17: W26
A18: Demand FC (Gross requirement) | B18: =SUMPRODUCT(B2:B7,$D$10:$D$15) -> 16670.019 | C18: =SUMPRODUCT(C2:C7,$D$10:$D$15) -> 16670.019 | D18: =SUMPRODUCT(D2:D7,$D$10:$D$15) -> 16670.019 | E18: =SUMPRODUCT(E2:E7,$D$10:$D$15) -> 16670.019 | F18: =SUMPRODUCT(F2:F7,$D$10:$D$15) -> 16670.019 | G18: =SUMPRODUCT(G2:G7,$D$10:$D$15) -> 16670.019 | H18: =SUMPRODUCT(H2:H7,$D$10:$D$15) -> 16670.019 | I18: =SUMPRODUCT(I2:I7,$D$10:$D$15) -> 16670.019 | ... AA18: =SUMPRODUCT(AA2:AA7,$D$10:$D$15) -> 16670.019
A19: Current stock/ Opening stock (Assumption: Opening stock W1=average inv) | B19: =$J$13*AVERAGE(B18:AA18) -> 41675.048 | C19: =B20 -> 25005.029 | D19: =C20 -> 68335.01 | E19: =D20 -> 51664.99 | F19: =E20 -> 34994.971 | G19: =F20 -> 78324.952 | H19: =G20 -> 61654.933 | I19: =H20 -> 44984.914 | J19: =I20 -> 28314.895 | ... AA19: =Z20 -> -45075.427
A20: Stock development (Closing stock) | B20: =B19-B18+B22 -> 25005.029 | C20: =C19-C18+C22 -> 68335.01 | D20: =D19-D18+D22 -> 51664.99 | E20: =E19-E18+E22 -> 34994.971 | F20: =F19-F18+F22 -> 78324.952 | G20: =G19-G18+G22 -> 61654.933 | H20: =H19-H18+H22 -> 44984.914 | I20: =I19-I18+I22 -> 28314.895 | ... AA20: =AA19-AA18+AA22 -> -31745.446
A21: Safety stock | B21: =SUM(B18:C18) -> 33340.038 | C21: =SUM(C18:D18) -> 33340.038 | D21: =SUM(D18:E18) -> 33340.038 | E21: =SUM(E18:F18) -> 33340.038 | F21: =SUM(F18:G18) -> 33340.038 | G21: =SUM(G18:H18) -> 33340.038 | H21: =SUM(H18:I18) -> 33340.038 | I21: =SUM(I18:J18) -> 33340.038 | ... AA21: =SUM(AA18:AB18) -> 16670.019
A22: Requirement new order (Net requirement) when closing stock < safety stock | C22: 60000 | F22: 60000 | N22: 30000 | P22: 30000 | R22: 30000 | S22: 30000 | U22: 30000 | W22: 30000 | Y22: 30000 | AA22: 30000
A23: Place order | B23: 30000 | D23: =F22 -> 60000 | E23: =G22 | F23: =H22 | G23: =I22 | H23: =J22 | I23: =K22 | J23: =L22 | K23: =M22 | ... AA23: =AC22
A24: Tank requirement | B24: =B20/30000 -> 0.83350095 | C24: =C20/30000 -> 2.2778336 | D24: =D20/30000 -> 1.7221663 | E24: =E20/30000 -> 1.1664991 | F24: =F20/30000 -> 2.6108318 | G24: =G20/30000 -> 2.0551644 | H24: =H20/30000 -> 1.4994972 | I24: =I20/30000 -> 0.94382985 | ... AA24: =AA20/30000 -> -1.0581816
A26: Mango | B26: W1 | C26: W2 | D26: W3 | E26: W4 | F26: W5 | G26: W6 | H26: W7 | I26: W8 | J26: W9 | K26: W10 | L26: W11 | M26: W12 | N26: W13 | O26: W14 | P26: W15 | Q26: W16 | R26: W17 | S26: W18 | T26: W19 | U26: W20 | V26: W21 | W26: W22 | X26: W23 | Y26: W24 | Z26: W25 | AA26: W26
A27: Demand FC | B27: =SUMPRODUCT(B2:B7,$E$10:$E$15) -> 1700.52 | C27: =SUMPRODUCT(C2:C7,$E$10:$E$15) -> 1700.52 | D27: =SUMPRODUCT(D2:D7,$E$10:$E$15) -> 1700.52 | E27: =SUMPRODUCT(E2:E7,$E$10:$E$15) -> 1700.52 | F27: =SUMPRODUCT(F2:F7,$E$10:$E$15) -> 1700.52 | G27: =SUMPRODUCT(G2:G7,$E$10:$E$15) -> 1700.52 | H27: =SUMPRODUCT(H2:H7,$E$10:$E$15) -> 1700.52 | I27: =SUMPRODUCT(I2:I7,$E$10:$E$15) -> 1700.52 | ... AA27: =SUMPRODUCT(AA2:AA7,$E$10:$E$15) -> 1700.52
A28: Current stock/ Opening stock | B28: 10000 | C28: =B29 -> 8299.48 | D28: =C29 -> 6598.96 | E28: =D29 -> 4898.44 | F28: =E29 -> 8197.92 | G28: =F29 -> 6497.4 | H28: =G29 -> 9796.88 | I28: =H29 -> 8096.36 | J28: =I29 -> 6395.84 | ... AA28: =Z29 -> 7487
A29: Stock development | B29: =B28-B27+B31 -> 8299.48 | C29: =B29-C27+C31 -> 6598.96 | D29: =C29-D27+D31 -> 4898.44 | E29: =D29-E27+E31 -> 8197.92 | F29: =E29-F27+F31 -> 6497.4 | G29: =F29-G27+G31 -> 9796.88 | H29: =G29-H27+H31 -> 8096.36 | I29: =H29-I27+I31 -> 6395.84 | J29: =I29-J27+J31 -> 9695.32 | ... AA29: =Z29-AA27+AA31 -> 5786.48
A30: Safety stock | B30: =SUM(B27:D27) -> 5101.56 | C30: =SUM(C27:E27) -> 5101.56 | D30: =SUM(D27:F27) -> 5101.56 | E30: =SUM(E27:G27) -> 5101.56 | F30: =SUM(F27:H27) -> 5101.56 | G30: =SUM(G27:I27) -> 5101.56 | H30: =SUM(H27:J27) -> 5101.56 | I30: =SUM(I27:K27) -> 5101.56 | ... AA30: =SUM(AA27:AC27) -> 1700.52
A31: Requirement new order | E31: 5000 | G31: 5000 | J31: 5000 | M31: 5000 | P31: 5000 | S31: 5000 | V31: 5000 | Y31: 5000
A32: Place order | B32: =D31 | C32: =E31 -> 5000 | D32: =F31 | E32: =G31 -> 5000 | F32: =H31 | G32: =I31 | H32: =J31 -> 5000 | I32: =K31 | ... AA32: =AC31
E33: 2000 | F33: 2000 | G33: 2000 | H33: 2000 | I33: 2000 | J33: 2000 | K33: 2000 | M33: 2000 | N33: 2000 | O33: 2000 | P33: 2000 | Q33: 2000 | S33: 2000 | T33: 2000 | U33: 2000 | V33: 2000 | W33: 2000 | Y33: 2000 | AA33: 2000
I36: Kiểu như này
